Workbook
Name _sell_platform: [1]销售平台!$A$2:$A$74
Name COUNTRY: [1]国家简码详情!$C$2:$C$272
Name STATE_US: [2]美国州省!$C$2:$C$58
Name WAREHOUSE: [1]仓库代码!$B$2:$B$6

Sheet 海外库存总表
A1: 查询编号 FNSKU/EAN | B1: sku | C1: 仓库 | D1: Material Code 料号代码 | E1: Chinese description of goods 中文品名 | F1: 产品系列 | G1: 产品系列2 | H1: Model 型号 | I1: 库存数量 | J1: 库存预警 | K1: 在途数量 | L1: 待接收及转运数量
A2: 6975925240203 | B2: 1300100048 | C2: 美西仓库 | D2: 1300100048 | E2: =VLOOKUP(D2,[2]SKU!A:AK,2,0) -> Mole Connect手机云台(安卓版)(英文版） | F2: =VLOOKUP(D2,[2]SKU!A:AK,8,0) -> 三维扫描仪备品备件 | G2: - | H2: =VLOOKUP(D2,[2]SKU!A:AK,26,0) -> - | I2: =VLOOKUP(A2,[2]谷仓US!A:P,15,0) -> 42 | J2: =IF(I2=0,"-",IF(VLOOKUP(A2,[2]谷仓US库龄!A:I,9,0)>365,"≥1 Year",IF(VLOOKUP(A2,[2]谷仓US库龄!A:I,9,0)>270,"≥9 Months",IF(VLOOKUP(A2,[2]谷仓US库龄!A:I,9,0)>180,"≥6 Months",IF(VLOOKUP(A2,[2]谷仓US库龄!A:I,9,0)>90,"≥3 Months","正常"))))) -> ≥1 Year | K2: =IF(VLOOKUP(A2,[2]谷仓US!A:P,12,0)=0,"",VLOOKUP(A2,[2]谷仓US!A:P,12,0))
A3: 6975925240210 | B3: 1300100047 | C3: 美西仓库 | D3: 1300100047 | E3: =VLOOKUP(D3,[2]SKU!A:AK,2,0) -> Mole Connect手机云台(苹果版)(英文版） | F3: =VLOOKUP(D3,[2]SKU!A:AK,8,0) -> 三维扫描仪备品备件 | G3: - | H3: =VLOOKUP(D3,[2]SKU!A:AK,26,0) -> - | I3: =VLOOKUP(A3,[2]谷仓US!A:P,15,0) -> 94 | J3: =IF(I3=0,"-",IF(VLOOKUP(A3,[2]谷仓US库龄!A:I,9,0)>365,"≥1 Year",IF(VLOOKUP(A3,[2]谷仓US库龄!A:I,9,0)>270,"≥9 Months",IF(VLOOKUP(A3,[2]谷仓US库龄!A:I,9,0)>180,"≥6 Months",IF(VLOOKUP(A3,[2]谷仓US库龄!A:I,9,0)>90,"≥3 Months","正常"))))) -> ≥1 Year | K3: =IF(VLOOKUP(A3,[2]谷仓US!A:P,12,0)=0,"",VLOOKUP(A3,[2]谷仓US!A:P,12,0))
A4: 6975925241293 | B4: 1300100219 | C4: 美西仓库 | D4: 1300100219 | E4: 三维扫描仪Seal基础款(4规) | F4: 三维扫描仪-JMS2 | G4: Seal基础 | H4: =VLOOKUP(D4,[2]SKU!A:AK,26,0) -> JMS2 | I4: =VLOOKUP(A4,[2]谷仓US!A:P,15,0) -> 1 | J4: =IF(I4=0,"-",IF(VLOOKUP(A4,[2]谷仓US库龄!A:I,9,0)>365,"≥1 Year",IF(VLOOKUP(A4,[2]谷仓US库龄!A:I,9,0)>270,"≥9 Months",IF(VLOOKUP(A4,[2]谷仓US库龄!A:I,9,0)>180,"≥6 Months",IF(VLOOKUP(A4,[2]谷仓US库龄!A:I,9,0)>90,"≥3 Months","正常"))))) -> 正常 | K4: =IF(VLOOKUP(A4,[2]谷仓US!A:P,12,0)=0,"",VLOOKUP(A4,[2]谷仓US!A:P,12,0)) -> 96
A5: 6975925241323 | B5: 1300100222 | C5: 美西仓库 | D5: 1300100222 | E5: 三维扫描仪Seal Lite基础款(4规) | F5: 三维扫描仪-JMS1 | G5: Seal Lite基础 | H5: =VLOOKUP(D5,[2]SKU!A:AK,26,0) -> JMS1 | I5: =VLOOKUP(A5,[2]谷仓US!A:P,15,0) -> 72 | J5: =IF(I5=0,"-",IF(VLOOKUP(A5,[2]谷仓US库龄!A:I,9,0)>365,"≥1 Year",IF(VLOOKUP(A5,[2]谷仓US库龄!A:I,9,0)>270,"≥9 Months",IF(VLOOKUP(A5,[2]谷仓US库龄!A:I,9,0)>180,"≥6 Months",IF(VLOOKUP(A5,[2]谷仓US库龄!A:I,9,0)>90,"≥3 Months","正常"))))) -> 正常 | K5: =IF(VLOOKUP(A5,[2]谷仓US!A:P,12,0)=0,"",VLOOKUP(A5,[2]谷仓US!A:P,12,0)) -> 32
A6: 6975925240746 | B6: 1300100118 | C6: 美西仓库 | D6: 1300100118 | E6: =VLOOKUP(D6,[2]SKU!A:AK,2,0) -> Seal/Seal lite转台套餐 | F6: 三维扫描仪备品备件 | G6: 普通转台 | H6: =VLOOKUP(D6,[2]SKU!A:AK,26,0) -> - | I6: =VLOOKUP(A6,[2]谷仓US!A:P,15,0) -> 92 | J6: =IF(I6=0,"-",IF(VLOOKUP(A6,[2]谷仓US库龄!A:I,9,0)>365,"≥1 Year",IF(VLOOKUP(A6,[2]谷仓US库龄!A:I,9,0)>270,"≥9 Months",IF(VLOOKUP(A6,[2]谷仓US库龄!A:I,9,0)>180,"≥6 Months",IF(VLOOKUP(A6,[2]谷仓US库龄!A:I,9,0)>90,"≥3 Months","正常"))))) -> 正常 | K6: =IF(VLOOKUP(A6,[2]谷仓US!A:P,12,0)=0,"",VLOOKUP(A6,[2]谷仓US!A:P,12,0)) -> 300
A7: 6975925240753 | B7: 1200100064 | C7: 美西仓库 | D7: 1200100064 | E7: =VLOOKUP(D7,[2]SKU!A:AK,2,0) -> Seal三脚架套装 | F7: =VLOOKUP(D7,[2]SKU!A:AK,8,0) -> 三维扫描仪备品备件 | G7: 三脚架 | H7: =VLOOKUP(D7,[2]SKU!A:AK,26,0) -> - | I7: =VLOOKUP(A7,[2]谷仓US!A:P,15,0) -> 25 | J7: =IF(I7=0,"-",IF(VLOOKUP(A7,[2]谷仓US库龄!A:I,9,0)>365,"≥1 Year",IF(VLOOKUP(A7,[2]谷仓US库龄!A:I,9,0)>270,"≥9 Months",IF(VLOOKUP(A7,[2]谷仓US库龄!A:I,9,0)>180,"≥6 Months",IF(VLOOKUP(A7,[2]谷仓US库龄!A:I,9,0)>90,"≥3 Months","正常"))))) -> ≥3 Months | K7: =IF(VLOOKUP(A7,[2]谷仓US!A:P,12,0)=0,"",VLOOKUP(A7,[2]谷仓US!A:P,12,0)) -> 100
A8: 6975925240739 | B8: 1300100082 | C8: 美西仓库 | D8: 1300100082 | E8: =VLOOKUP(D8,[2]SKU!A:AK,2,0) -> 三维扫描仪智能手柄 | F8: =VLOOKUP(D8,[2]SKU!A:AK,8,0) -> 三维扫描仪备品备件 | G8: 智能手柄 | H8: =VLOOKUP(D8,[2]SKU!A:AK,26,0) -> JMB1 | I8: =VLOOKUP(A8,[2]谷仓US!A:P,15,0) -> 0 | J8: =IF(I8=0,"-",IF(VLOOKUP(A8,[2]谷仓US库龄!A:I,9,0)>365,"≥1 Year",IF(VLOOKUP(A8,[2]谷仓US库龄!A:I,9,0)>270,"≥9 Months",IF(VLOOKUP(A8,[2]谷仓US库龄!A:I,9,0)>180,"≥6 Months",IF(VLOOKUP(A8,[2]谷仓US库龄!A:I,9,0)>90,"≥3 Months","正常"))))) -> - | K8: =IF(VLOOKUP(A8,[2]谷仓US!A:P,12,0)=0,"",VLOOKUP(A8,[2]谷仓US!A:P,12,0)) -> 60
A9: 6975925241033 | B9: 1021900174 | C9: 美西仓库 | D9: 1021900174 | E9: =VLOOKUP(D9,[2]SKU!A:AK,2,0) -> 智能手柄数据线 | F9: =VLOOKUP(D9,[2]SKU!A:AK,8,0) -> 三维扫描仪备品备件 | G9: - | H9: =VLOOKUP(D9,[2]SKU!A:AK,26,0) -> - | I9: =VLOOKUP(A9,[2]谷仓US!A:P,15,0) -> 116 | J9: =IF(I9=0,"-",IF(VLOOKUP(A9,[2]谷仓US库龄!A:I,9,0)>365,"≥1 Year",IF(VLOOKUP(A9,[2]谷仓US库龄!A:I,9,0)>270,"≥9 Months",IF(VLOOKUP(A9,[2]谷仓US库龄!A:I,9,0)>180,"≥6 Months",IF(VLOOKUP(A9,[2]谷仓US库龄!A:I,9,0)>90,"≥3 Months","正常"))))) -> ≥1 Year | K9: =IF(VLOOKUP(A9,[2]谷仓US!A:P,12,0)=0,"",VLOOKUP(A9,[2]谷仓US!A:P,12,0))
A10: 6975925240227 | B10: 1300100066 | C10: 美西仓库 | D10: 1300100066 | E10: =VLOOKUP(D10,[2]SKU!A:AK,2,0) -> Mole三脚架套餐 | F10: =VLOOKUP(D10,[2]SKU!A:AK,8,0) -> 三维扫描仪备品备件 | G10: - | H10: =VLOOKUP(D10,[2]SKU!A:AK,26,0) -> - | I10: =VLOOKUP(A10,[2]谷仓US!A:P,15,0) -> 17 | J10: =IF(I10=0,"-",IF(VLOOKUP(A10,[2]谷仓US库龄!A:I,9,0)>365,"≥1 Year",IF(VLOOKUP(A10,[2]谷仓US库龄!A:I,9,0)>270,"≥9 Months",IF(VLOOKUP(A10,[2]谷仓US库龄!A:I,9,0)>180,"≥6 Months",IF(VLOOKUP(A10,[2]谷仓US库龄!A:I,9,0)>90,"≥3 Months","正常"))))) -> ≥1 Year | K10: =IF(VLOOKUP(A10,[2]谷仓US!A:P,12,0)=0,"",VLOOKUP(A10,[2]谷仓US!A:P,12,0))
A11: 6975925240272 | B11: 1300100073 | C11: 美西仓库 | D11: 1300100073 | E11: =VLOOKUP(D11,[2]SKU!A:AK,2,0) -> Lynx三脚架套餐 | F11: =VLOOKUP(D11,[2]SKU!A:AK,8,0) -> 三维扫描仪备品备件 | G11: - | H11: =VLOOKUP(D11,[2]SKU!A:AK,26,0) -> - | I11: =VLOOKUP(A11,[2]谷仓US!A:P,15,0) -> 28 | J11: =IF(I11=0,"-",IF(VLOOKUP(A11,[2]谷仓US库龄!A:I,9,0)>365,"≥1 Year",IF(VLOOKUP(A11,[2]谷仓US库龄!A:I,9,0)>270,"≥9 Months",IF(VLOOKUP(A11,[2]谷仓US库龄!A:I,9,0)>180,"≥6 Months",IF(VLOOKUP(A11,[2]谷仓US库龄!A:I,9,0)>90,"≥3 Months","正常"))))) -> ≥1 Year | K11: =IF(VLOOKUP(A11,[2]谷仓US!A:P,12,0)=0,"",VLOOKUP(A11,[2]谷仓US!A:P,12,0))
A12: 6975925241354 | B12: 1300100139 | C12: 美西仓库 | D12: 1300100139 | E12: =VLOOKUP(D12,[2]SKU!A:AK,2,0) -> Seal双轴转台(美规) | F12: =VLOOKUP(D12,[2]SKU!A:AK,8,0) -> 三维扫描仪备品备件 | G12: 双轴转台 | H12: =VLOOKUP(D12,[2]SKU!A:AK,26,0) -> - | I12: =VLOOKUP(A12,[2]谷仓US!A:P,15,0) -> 23 | J12: =IF(I12=0,"-",IF(VLOOKUP(A12,[2]谷仓US库龄!A:I,9,0)>365,"≥1 Year",IF(VLOOKUP(A12,[2]谷仓US库龄!A:I,9,0)>270,"≥9 Months",IF(VLOOKUP(A12,[2]谷仓US库龄!A:I,9,0)>180,"≥6 Months",IF(VLOOKUP(A12,[2]谷仓US库龄!A:I,9,0)>90,"≥3 Months","正常"))))) -> 正常 | K12: =IF(VLOOKUP(A12,[2]谷仓US!A:P,12,0)=0,"",VLOOKUP(A12,[2]谷仓US!A:P,12,0)) -> 40
A13: 6975925241378 | B13: 1300100229 | C13: 美西仓库 | D13: 1300100229 | E13: 三维扫描仪Moose基础款(4规) | F13: =VLOOKUP(D13,[2]SKU!A:AK,8,0) -> 三维扫描仪-JMM3 | G13: Moose基础 | H13: =VLOOKUP(D13,[2]SKU!A:AK,26,0) -> JMM3 | I13: =VLOOKUP(A13,[2]谷仓US!A:P,15,0) -> 52 | J13: =IF(I13=0,"-",IF(VLOOKUP(A13,[2]谷仓US库龄!A:I,9,0)>365,"≥1 Year",IF(VLOOKUP(A13,[2]谷仓US库龄!A:I,9,0)>270,"≥9 Months",IF(VLOOKUP(A13,[2]谷仓US库龄!A:I,9,0)>180,"≥6 Months",IF(VLOOKUP(A13,[2]谷仓US库龄!A:I,9,0)>90,"≥3 Months","正常"))))) -> 正常 | K13: =IF(VLOOKUP(A13,[2]谷仓US!A:P,12,0)=0,"",VLOOKUP(A13,[2]谷仓US!A:P,12,0)) -> 20
A14: 6975925241385 | B14: 1300100230 | C14: 美西仓库 | D14: 1300100230 | E14: 三维扫描仪Moose升级款(4规) | F14: 三维扫描仪-JMM3 | G14: Moose升级 | H14: JMM3 | I14: =VLOOKUP(A14,[2]谷仓US!A:P,15,0) -> 41 | J14: =IF(I14=0,"-",IF(VLOOKUP(A14,[2]谷仓US库龄!A:I,9,0)>365,"≥1 Year",IF(VLOOKUP(A14,[2]谷仓US库龄!A:I,9,0)>270,"≥9 Months",IF(VLOOKUP(A14,[2]谷仓US库龄!A:I,9,0)>180,"≥6 Months",IF(VLOOKUP(A14,[2]谷仓US库龄!A:I,9,0)>90,"≥3 Months","正常"))))) -> 正常 | K14: =IF(VLOOKUP(A14,[2]谷仓US!A:P,12,0)=0,"",VLOOKUP(A14,[2]谷仓US!A:P,12,0))
A15: 6975925241392 | B15: 1300100231 | C15: 美西仓库 | D15: 1300100231 | E15: 三维扫描仪Moose豪华款(4规) | F15: =VLOOKUP(D15,[2]SKU!A:AK,8,0) -> 三维扫描仪-JMM3 | G15: Moose豪华 | H15: =VLOOKUP(D15,[2]SKU!A:AK,26,0) -> JMM3 | I15: =VLOOKUP(A15,[2]谷仓US!A:P,15,0) -> 0 | J15: =IF(I15=0,"-",IF(VLOOKUP(A15,[2]谷仓US库龄!A:I,9,0)>365,"≥1 Year",IF(VLOOKUP(A15,[2]谷仓US库龄!A:I,9,0)>270,"≥9 Months",IF(VLOOKUP(A15,[2]谷仓US库龄!A:I,9,0)>180,"≥6 Months",IF(VLOOKUP(A15,[2]谷仓US库龄!A:I,9,0)>90,"≥3 Months","正常"))))) -> - | K15: =IF(VLOOKUP(A15,[2]谷仓US!A:P,12,0)=0,"",VLOOKUP(A15,[2]谷仓US!A:P,12,0))
A16: 6975925241408 | B16: 1300100232 | C16: 美西仓库 | D16: 1300100232 | E16: 三维扫描仪Moose Lite基础款(4规) | F16: =VLOOKUP(D16,[2]SKU!A:AK,8,0) -> 三维扫描仪-JMM4 | G16: Moose Lite基础 | H16: =VLOOKUP(D16,[2]SKU!A:AK,26,0) -> JMM4 | I16: =VLOOKUP(A16,[2]谷仓US!A:P,15,0) -> 7 | J16: =IF(I16=0,"-",IF(VLOOKUP(A16,[2]谷仓US库龄!A:I,9,0)>365,"≥1 Year",IF(VLOOKUP(A16,[2]谷仓US库龄!A:I,9,0)>270,"≥9 Months",IF(VLOOKUP(A16,[2]谷仓US库龄!A:I,9,0)>180,"≥6 Months",IF(VLOOKUP(A16,[2]谷仓US库龄!A:I,9,0)>90,"≥3 Months","正常"))))) -> 正常 | K16: =IF(VLOOKUP(A16,[2]谷仓US!A:P,12,0)=0,"",VLOOKUP(A16,[2]谷仓US!A:P,12,0)) -> 240
A17: 6975925241415 | B17: 1300100233 | C17: 美西仓库 | D17: 1300100233 | E17: 三维扫描仪Moose Lite升级款(4规) | F17: 三维扫描仪-JMM4 | G17: Moose Lite升级 | H17: JMM4 | I17: =VLOOKUP(A17,[2]谷仓US!A:P,15,0) -> 0 | J17: =IF(I17=0,"-",IF(VLOOKUP(A17,[2]谷仓US库龄!A:I,9,0)>365,"≥1 Year",IF(VLOOKUP(A17,[2]谷仓US库龄!A:I,9,0)>270,"≥9 Months",IF(VLOOKUP(A17,[2]谷仓US库龄!A:I,9,0)>180,"≥6 Months",IF(VLOOKUP(A17,[2]谷仓US库龄!A:I,9,0)>90,"≥3 Months","正常"))))) -> - | K17: =IF(VLOOKUP(A17,[2]谷仓US!A:P,12,0)=0,"",VLOOKUP(A17,[2]谷仓US!A:P,12,0)) -> 36
A18: 6975925241422 | B18: 1300100234 | C18: 美西仓库 | D18: 1300100234 | E18: =VLOOKUP(D18,[2]SKU!A:AK,2,0) -> 三维扫描仪Moose Lite豪华款(4规) | F18: =VLOOKUP(D18,[2]SKU!A:AK,8,0) -> 三维扫描仪-JMM4 | G18: Moose Lite豪华 | H18: =VLOOKUP(D18,[2]SKU!A:AK,26,0) -> JMM4 | I18: =VLOOKUP(A18,[2]谷仓US!A:P,15,0) -> 12 | J18: =IF(I18=0,"-",IF(VLOOKUP(A18,[2]谷仓US库龄!A:I,9,0)>365,"≥1 Year",IF(VLOOKUP(A18,[2]谷仓US库龄!A:I,9,0)>270,"≥9 Months",IF(VLOOKUP(A18,[2]谷仓US库龄!A:I,9,0)>180,"≥6 Months",IF(VLOOKUP(A18,[2]谷仓US库龄!A:I,9,0)>90,"≥3 Months","正常"))))) -> ≥9 Months | K18: =IF(VLOOKUP(A18,[2]谷仓US!A:P,12,0)=0,"",VLOOKUP(A18,[2]谷仓US!A:P,12,0)) -> 40
A19: 6975925241231 | B19: 1300100211 | C19: 美西仓库 | D19: 1300100211 | E19: =VLOOKUP(D19,[2]SKU!A:AK,2,0) -> 三维扫描仪Eagle JMK1 RTK | F19: =VLOOKUP(D19,[2]SKU!A:AK,8,0) -> 三维扫描仪-JMK1 | G19: JMK1 RTK | H19: =VLOOKUP(D19,[2]SKU!A:AK,26,0) -> JMK1 | I19: =VLOOKUP(A19,[2]谷仓US!A:P,15,0) -> 12 | J19: =IF(I19=0,"-",IF(VLOOKUP(A19,[2]谷仓US库龄!A:I,9,0)>365,"≥1 Year",IF(VLOOKUP(A19,[2]谷仓US库龄!A:I,9,0)>270,"≥9 Months",IF(VLOOKUP(A19,[2]谷仓US库龄!A:I,9,0)>180,"≥6 Months",IF(VLOOKUP(A19,[2]谷仓US库龄!A:I,9,0)>90,"≥3 Months","正常"))))) -> 正常 | K19: =IF(VLOOKUP(A19,[2]谷仓US!A:P,12,0)=0,"",VLOOKUP(A19,[2]谷仓US!A:P,12,0)) -> 16
A20: 6975925241248 | B20: 1300100212 | C20: 美西仓库 | D20: 1300100212 | E20: =VLOOKUP(D20,[2]SKU!A:AK,2,0) -> 三维扫描仪Eagle JMK2 RTK | F20: =VLOOKUP(D20,[2]SKU!A:AK,8,0) -> 三维扫描仪-JMK2 | G20: JMK2 RTK | H20: =VLOOKUP(D20,[2]SKU!A:AK,26,0) -> JMK2 | I20: =VLOOKUP(A20,[2]谷仓US!A:P,15,0) -> 19 | J20: =IF(I20=0,"-",IF(VLOOKUP(A20,[2]谷仓US库龄!A:I,9,0)>365,"≥1 Year",IF(VLOOKUP(A20,[2]谷仓US库龄!A:I,9,0)>270,"≥9 Months",IF(VLOOKUP(A20,[2]谷仓US库龄!A:I,9,0)>180,"≥6 Months",IF(VLOOKUP(A20,[2]谷仓US库龄!A:I,9,0)>90,"≥3 Months","正常"))))) -> ≥3 Months | K20: =IF(VLOOKUP(A20,[2]谷仓US!A:P,12,0)=0,"",VLOOKUP(A20,[2]谷仓US!A:P,12,0)) -> 12
A21: 6975925241187 | B21: 1300100205 | C21: 美西仓库 | D21: 1300100205 | E21: =VLOOKUP(D21,[2]SKU!A:AK,2,0) -> 钢化膜套装 | F21: =VLOOKUP(D21,[2]SKU!A:AK,8,0) -> 三维扫描仪备品备件 | G21: - | H21: =VLOOKUP(D21,[2]SKU!A:AK,26,0) -> - | I21: =VLOOKUP(A21,[2]谷仓US!A:P,15,0) -> 33 | J21: =IF(I21=0,"-",IF(VLOOKUP(A21,[2]谷仓US库龄!A:I,9,0)>365,"≥1 Year",IF(VLOOKUP(A21,[2]谷仓US库龄!A:I,9,0)>270,"≥9 Months",IF(VLOOKUP(A21,[2]谷仓US库龄!A:I,9,0)>180,"≥6 Months",IF(VLOOKUP(A21,[2]谷仓US库龄!A:I,9,0)>90,"≥3 Months","正常"))))) -> ≥1 Year | K21: =IF(VLOOKUP(A21,[2]谷仓US!A:P,12,0)=0,"",VLOOKUP(A21,[2]谷仓US!A:P,12,0))
A22: 6975925241194 | B22: 1050100021 | C22: 美西仓库 | D22: 1050100021 | E22: =VLOOKUP(D22,[2]SKU!A:AK,2,0) -> 三脚架 | F22: =VLOOKUP(D22,[2]SKU!A:AK,8,0) -> 三维扫描仪备品备件 | G22: - | H22: =VLOOKUP(D22,[2]SKU!A:AK,26,0) -> - | I22: =VLOOKUP(A22,[2]谷仓US!A:P,15,0) -> 15 | J22: =IF(I22=0,"-",IF(VLOOKUP(A22,[2]谷仓US库龄!A:I,9,0)>365,"≥1 Year",IF(VLOOKUP(A22,[2]谷仓US库龄!A:I,9,0)>270,"≥9 Months",IF(VLOOKUP(A22,[2]谷仓US库龄!A:I,9,0)>180,"≥6 Months",IF(VLOOKUP(A22,[2]谷仓US库龄!A:I,9,0)>90,"≥3 Months","正常"))))) -> ≥9 Months | K22: =IF(VLOOKUP(A22,[2]谷仓US!A:P,12,0)=0,"",VLOOKUP(A22,[2]谷仓US!A:P,12,0))
A23: 6975925241217 | B23: 1300100208 | C23: 美西仓库 | D23: 1300100208 | E23: 背架套装 | F23: =VLOOKUP(D23,[2]SKU!A:AK,8,0) -> 三维扫描仪备品备件 | G23: - | H23: =VLOOKUP(D23,[2]SKU!A:AK,26,0) -> - | I23: =VLOOKUP(A23,[2]谷仓US!A:P,15,0) -> 0 | J23: =IF(I23=0,"-",IF(VLOOKUP(A23,[2]谷仓US库龄!A:I,9,0)>365,"≥1 Year",IF(VLOOKUP(A23,[2]谷仓US库龄!A:I,9,0)>270,"≥9 Months",IF(VLOOKUP(A23,[2]谷仓US库龄!A:I,9,0)>180,"≥6 Months",IF(VLOOKUP(A23,[2]谷仓US库龄!A:I,9,0)>90,"≥3 Months","正常"))))) -> - | K23: =IF(VLOOKUP(A23,[2]谷仓US!A:P,12,0)=0,"",VLOOKUP(A23,[2]谷仓US!A:P,12,0))
A24: 6975925241279 | B24: 1021900168 | C24: 美西仓库 | D24: 1021900168 | E24: =VLOOKUP(D24,[2]SKU!A:AK,2,0) -> Moose一体线缆 | F24: =VLOOKUP(D24,[2]SKU!A:AK,8,0) -> 三维扫描仪备品备件 | G24: - | H24: =VLOOKUP(D24,[2]SKU!A:AK,26,0) -> - | I24: =VLOOKUP(A24,[2]谷仓US!A:P,15,0) -> 49 | J24: =IF(I24=0,"-",IF(VLOOKUP(A24,[2]谷仓US库龄!A:I,9,0)>365,"≥1 Year",IF(VLOOKUP(A24,[2]谷仓US库龄!A:I,9,0)>270,"≥9 Months",IF(VLOOKUP(A24,[2]谷仓US库龄!A:I,9,0)>180,"≥6 Months",IF(VLOOKUP(A24,[2]谷仓US库龄!A:I,9,0)>90,"≥3 Months","正常"))))) -> ≥1 Year | K24: =IF(VLOOKUP(A24,[2]谷仓US!A:P,12,0)=0,"",VLOOKUP(A24,[2]谷仓US!A:P,12,0))
A25: 6975925240807 | B25: 1021900094 | C25: 美西仓库 | D25: 1021900094 | E25: =VLOOKUP(D25,[2]SKU!A:AK,2,0) -> Seal扫描仪订制一体线缆 | F25: =VLOOKUP(D25,[2]SKU!A:AK,8,0) -> 三维扫描仪备品备件 | G25: - | H25: =VLOOKUP(D25,[2]SKU!A:AK,26,0) -> - | I25: =VLOOKUP(A25,[2]谷仓US!A:P,15,0) -> 7 | J25: =IF(I25=0,"-",IF(VLOOKUP(A25,[2]谷仓US库龄!A:I,9,0)>365,"≥1 Year",IF(VLOOKUP(A25,[2]谷仓US库龄!A:I,9,0)>270,"≥9 Months",IF(VLOOKUP(A25,[2]谷仓US库龄!A:I,9,0)>180,"≥6 Months",IF(VLOOKUP(A25,[2]谷仓US库龄!A:I,9,0)>90,"≥3 Months","正常"))))) -> ≥1 Year | K25: =IF(VLOOKUP(A25,[2]谷仓US!A:P,12,0)=0,"",VLOOKUP(A25,[2]谷仓US!A:P,12,0))
A26: 6975925241286 | B26: 1040600057 | C26: 美西仓库 | D26: 1040600057 | E26: =VLOOKUP(D26,[2]SKU!A:AK,2,0) -> PD电源 | F26: =VLOOKUP(D26,[2]SKU!A:AK,8,0) -> 三维扫描仪备品备件 | G26: - | H26: =VLOOKUP(D26,[2]SKU!A:AK,26,0) -> RH-PD65W-1 | I26: =VLOOKUP(A26,[2]谷仓US!A:P,15,0) -> 14 | J26: =IF(I26=0,"-",IF(VLOOKUP(A26,[2]谷仓US库龄!A:I,9,0)>365,"≥1 Year",IF(VLOOKUP(A26,[2]谷仓US库龄!A:I,9,0)>270,"≥9 Months",IF(VLOOKUP(A26,[2]谷仓US库龄!A:I,9,0)>180,"≥6 Months",IF(VLOOKUP(A26,[2]谷仓US库龄!A:I,9,0)>90,"≥3 Months","正常"))))) -> ≥1 Year | K26: =IF(VLOOKUP(A26,[2]谷仓US!A:P,12,0)=0,"",VLOOKUP(A26,[2]谷仓US!A:P,12,0))
A27: 6975925241224 | B27: 1300100209 | C27: 美西仓库 | D27: 1300100209 | E27: =VLOOKUP(D27,[2]SKU!A:AK,2,0) -> 自行车支架套装 | F27: =VLOOKUP(D27,[2]SKU!A:AK,8,0) -> 三维扫描仪备品备件 | G27: - | H27: =VLOOKUP(D27,[2]SKU!A:AK,26,0) -> - | I27: =VLOOKUP(A27,[2]谷仓US!A:P,15,0) -> 0 | J27: =IF(I27=0,"-",IF(VLOOKUP(A27,[2]谷仓US库龄!A:I,9,0)>365,"≥1 Year",IF(VLOOKUP(A27,[2]谷仓US库龄!A:I,9,0)>270,"≥9 Months",IF(VLOOKUP(A27,[2]谷仓US库龄!A:I,9,0)>180,"≥6 Months",IF(VLOOKUP(A27,[2]谷仓US库龄!A:I,9,0)>90,"≥3 Months","正常"))))) -> - | K27: =IF(VLOOKUP(A27,[2]谷仓US!A:P,12,0)=0,"",VLOOKUP(A27,[2]谷仓US!A:P,12,0)) -> 33
A28: 6975925241200 | B28: 1300100207 | C28: 美西仓库 | D28: 1300100207 | E28: =VLOOKUP(D28,[2]SKU!A:AK,2,0) -> 车顶吸盘安装套装 | F28: =VLOOKUP(D28,[2]SKU!A:AK,8,0) -> 三维扫描仪备品备件 | G28: - | H28: =VLOOKUP(D28,[2]SKU!A:AK,26,0) -> - | I28: =VLOOKUP(A28,[2]谷仓US!A:P,15,0) -> 19 | J28: =IF(I28=0,"-",IF(VLOOKUP(A28,[2]谷仓US库龄!A:I,9,0)>365,"≥1 Year",IF(VLOOKUP(A28,[2]谷仓US库龄!A:I,9,0)>270,"≥9 Months",IF(VLOOKUP(A28,[2]谷仓US库龄!A:I,9,0)>180,"≥6 Months",IF(VLOOKUP(A28,[2]谷仓US库龄!A:I,9,0)>90,"≥3 Months","正常"))))) -> 正常 | K28: =IF(VLOOKUP(A28,[2]谷仓US!A:P,12,0)=0,"",VLOOKUP(A28,[2]谷仓US!A:P,12,0))
A29: 6975925241514 | B29: 1300100246 | C29: 美西仓库 | D29: 1300100246 | E29: 三维扫描仪Toucan基础款(4规) | F29: 三维扫描仪-Toucan | G29: Toucan基础 | H29: JMM6 | I29: =VLOOKUP(A29,[2]谷仓US!A:P,15,0) -> 31 | J29: =IF(I29=0,"-",IF(VLOOKUP(A29,[2]谷仓US库龄!A:I,9,0)>365,"≥1 Year",IF(VLOOKUP(A29,[2]谷仓US库龄!A:I,9,0)>270,"≥9 Months",IF(VLOOKUP(A29,[2]谷仓US库龄!A:I,9,0)>180,"≥6 Months",IF(VLOOKUP(A29,[2]谷仓US库龄!A:I,9,0)>90,"≥3 Months","正常"))))) -> ≥3 Months | K29: =IF(VLOOKUP(A29,[2]谷仓US!A:P,12,0)=0,"",VLOOKUP(A29,[2]谷仓US!A:P,12,0))
A30: 6975925241453 | B30: 1300100240 | C30: 美西仓库 | D30: 1300100240 | E30: 三维扫描仪Toucan升级款(4规) | F30: 三维扫描仪-Toucan | G30: Toucan升级 | H30: JMM6 | I30: =VLOOKUP(A30,[2]谷仓US!A:P,15,0) -> 109 | J30: =IF(I30=0,"-",IF(VLOOKUP(A30,[2]谷仓US库龄!A:I,9,0)>365,"≥1 Year",IF(VLOOKUP(A30,[2]谷仓US库龄!A:I,9,0)>270,"≥9 Months",IF(VLOOKUP(A30,[2]谷仓US库龄!A:I,9,0)>180,"≥6 Months",IF(VLOOKUP(A30,[2]谷仓US库龄!A:I,9,0)>90,"≥3 Months","正常"))))) -> ≥3 Months | K30: =IF(VLOOKUP(A30,[2]谷仓US!A:P,12,0)=0,"",VLOOKUP(A30,[2]谷仓US!A:P,12,0))
A31: 6975925241538 | B31: 1300100249 | C31: 美西仓库 | D31: 1300100249 | E31: Toucan三脚架套装 | F31: 三维扫描仪备品备件 | G31: - | H31: - | I31: =VLOOKUP(A31,[2]谷仓US!A:P,15,0) -> 18 | J31: =IF(I31=0,"-",IF(VLOOKUP(A31,[2]谷仓US库龄!A:I,9,0)>365,"≥1 Year",IF(VLOOKUP(A31,[2]谷仓US库龄!A:I,9,0)>270,"≥9 Months",IF(VLOOKUP(A31,[2]谷仓US库龄!A:I,9,0)>180,"≥6 Months",IF(VLOOKUP(A31,[2]谷仓US库龄!A:I,9,0)>90,"≥3 Months","正常"))))) -> ≥3 Months | K31: =IF(VLOOKUP(A31,[2]谷仓US!A:P,12,0)=0,"",VLOOKUP(A31,[2]谷仓US!A:P,12,0))
A32: 6975925241521 | B32: 1300100250 | C32: 美西仓库 | D32: 1300100250 | E32: Toucan箱包套装 | F32: 三维扫描仪备品备件 | G32: - | H32: - | I32: =VLOOKUP(A32,[2]谷仓US!A:P,15,0) -> 35 | J32: =IF(I32=0,"-",IF(VLOOKUP(A32,[2]谷仓US库龄!A:I,9,0)>365,"≥1 Year",IF(VLOOKUP(A32,[2]谷仓US库龄!A:I,9,0)>270,"≥9 Months",IF(VLOOKUP(A32,[2]谷仓US库龄!A:I,9,0)>180,"≥6 Months",IF(VLOOKUP(A32,[2]谷仓US库龄!A:I,9,0)>90,"≥3 Months","正常"))))) -> ≥3 Months | K32: =IF(VLOOKUP(A32,[2]谷仓US!A:P,12,0)=0,"",VLOOKUP(A32,[2]谷仓US!A:P,12,0))
A33: 6975925241545 | B33: 1300100248 | C33: 美西仓库 | D33: 1300100248 | E33: MTT2转台 | F33: 三维扫描仪备品备件 | G33: MTT2转台 | H33: - | I33: =VLOOKUP(A33,[2]谷仓US!A:P,15,0) -> 10 | J33: =IF(I33=0,"-",IF(VLOOKUP(A33,[2]谷仓US库龄!A:I,9,0)>365,"≥1 Year",IF(VLOOKUP(A33,[2]谷仓US库龄!A:I,9,0)>270,"≥9 Months",IF(VLOOKUP(A33,[2]谷仓US库龄!A:I,9,0)>180,"≥6 Months",IF(VLOOKUP(A33,[2]谷仓US库龄!A:I,9,0)>90,"≥3 Months","正常"))))) -> 正常 | K33: =IF(VLOOKUP(A33,[2]谷仓US!A:P,12,0)=0,"",VLOOKUP(A33,[2]谷仓US!A:P,12,0))
A34: 6975925241446 | B34: 1300100241 | C34: 美西仓库 | D34: 1300100241 | E34: 三维扫描仪Hawk(4规) | F34: 三维扫描仪-Hawk | G34: JMK5 | H34: JMK5 | I34: =VLOOKUP(A34,[2]谷仓US!A:P,15,0) -> 0 | J34: =IF(I34=0,"-",IF(VLOOKUP(A34,[2]谷仓US库龄!A:I,9,0)>365,"≥1 Year",IF(VLOOKUP(A34,[2]谷仓US库龄!A:I,9,0)>270,"≥9 Months",IF(VLOOKUP(A34,[2]谷仓US库龄!A:I,9,0)>180,"≥6 Months",IF(VLOOKUP(A34,[2]谷仓US库龄!A:I,9,0)>90,"≥3 Months","正常"))))) -> - | K34: =IF(VLOOKUP(A34,[2]谷仓US!A:P,12,0)=0,"",VLOOKUP(A34,[2]谷仓US!A:P,12,0))
A35: 6975925241576 | B35: 1300100262 | C35: 美西仓库 | D35: 1300100262 | E35: 三维扫描仪Raven Max升级款(4规） | F35: 三维扫描仪-JMK6 | G35: JMK6升级 | H35: JMK6 | I35: =VLOOKUP(A35,[2]谷仓US!A:P,15,0) -> 27 | J35: =IF(I35=0,"-",IF(VLOOKUP(A35,[2]谷仓US库龄!A:I,9,0)>365,"≥1 Year",IF(VLOOKUP(A35,[2]谷仓US库龄!A:I,9,0)>270,"≥9 Months",IF(VLOOKUP(A35,[2]谷仓US库龄!A:I,9,0)>180,"≥6 Months",IF(VLOOKUP(A35,[2]谷仓US库龄!A:I,9,0)>90,"≥3 Months","正常"))))) -> 正常 | K35: =IF(VLOOKUP(A35,[2]谷仓US!A:P,12,0)=0,"",VLOOKUP(A35,[2]谷仓US!A:P,12,0))
A36: 6975925241569 | B36: 1300100256 | C36: 美西仓库 | D36: 1300100256 | E36: 三维扫描仪Raven Max基础款(4规) | F36: 三维扫描仪-JMK6 | G36: JMK6基础 | H36: JMK6 | I36: =VLOOKUP(A36,[2]谷仓US!A:P,15,0) -> 21 | J36: =IF(I36=0,"-",IF(VLOOKUP(A36,[2]谷仓US库龄!A:I,9,0)>365,"≥1 Year",IF(VLOOKUP(A36,[2]谷仓US库龄!A:I,9,0)>270,"≥9 Months",IF(VLOOKUP(A36,[2]谷仓US库龄!A:I,9,0)>180,"≥6 Months",IF(VLOOKUP(A36,[2]谷仓US库龄!A:I,9,0)>90,"≥3 Months","正常"))))) -> 正常 | K36: =IF(VLOOKUP(A36,[2]谷仓US!A:P,12,0)=0,"",VLOOKUP(A36,[2]谷仓US!A:P,12,0))
A37: 6975925241583 | B37: 1300100263 | C37: 美西仓库 | D37: 1300100263 | E37: 三维扫描仪Raven(4规) | F37: 三维扫描仪-JMK7 | G37: JMK7 | H37: JMK7 | I37: =VLOOKUP(A37,[2]谷仓US!A:P,15,0) -> 0 | J37: =IF(I37=0,"-",IF(VLOOKUP(A37,[2]谷仓US库龄!A:I,9,0)>365,"≥1 Year",IF(VLOOKUP(A37,[2]谷仓US库龄!A:I,9,0)>270,"≥9 Months",IF(VLOOKUP(A37,[2]谷仓US库龄!A:I,9,0)>180,"≥6 Months",IF(VLOOKUP(A37,[2]谷仓US库龄!A:I,9,0)>90,"≥3 Months","正常"))))) -> - | K37: =IF(VLOOKUP(A37,[2]谷仓US!A:P,12,0)=0,"",VLOOKUP(A37,[2]谷仓US!A:P,12,0))
A38: 6975925241613 | B38: 1300100260 | C38: 美西仓库 | D38: 1300100260 | E38: 三维扫描仪FOX(4规) | F38: 三维扫描仪-JMM8 | G38: FOX | H38: JMM8 | I38: =VLOOKUP(A38,[2]谷仓US!A:P,15,0) -> 86 | J38: =IF(I38=0,"-",IF(VLOOKUP(A38,[2]谷仓US库龄!A:I,9,0)>365,"≥1 Year",IF(VLOOKUP(A38,[2]谷仓US库龄!A:I,9,0)>270,"≥9 Months",IF(VLOOKUP(A38,[2]谷仓US库龄!A:I,9,0)>180,"≥6 Months",IF(VLOOKUP(A38,[2]谷仓US库龄!A:I,9,0)>90,"≥3 Months","正常"))))) -> 正常 | K38: =IF(VLOOKUP(A38,[2]谷仓US!A:P,12,0)=0,"",VLOOKUP(A38,[2]谷仓US!A:P,12,0)) -> 200
A39: 6975925241637 | B39: 1300100245 | C39: 美西仓库 | D39: 1300100245 | E39: 360相机套装 | F39: 三维扫描仪备品备件 | G39: - | H39: - | I39: =VLOOKUP(A39,[2]谷仓US!A:P,15,0) -> 32 | J39: =IF(I39=0,"-",IF(VLOOKUP(A39,[2]谷仓US库龄!A:I,9,0)>365,"≥1 Year",IF(VLOOKUP(A39,[2]谷仓US库龄!A:I,9,0)>270,"≥9 Months",IF(VLOOKUP(A39,[2]谷仓US库龄!A:I,9,0)>180,"≥6 Months",IF(VLOOKUP(A39,[2]谷仓US库龄!A:I,9,0)>90,"≥3 Months","正常"))))) -> 正常 | K39: =IF(VLOOKUP(A39,[2]谷仓US!A:P,12,0)=0,"",VLOOKUP(A39,[2]谷仓US!A:P,12,0)) -> 26
A40: 6975925240517 | B40: 1300100111 | C40: 德国仓库 | D40: 1300100111 | E40: =VLOOKUP(D40,[2]SKU!A:AK,2,0) -> 三维扫描仪Lynx基础款(欧规) | F40: =VLOOKUP(D40,[2]SKU!A:AK,8,0) -> 三维扫描仪-JML1 | G40: Lynx基础 | H40: =VLOOKUP(D40,[2]SKU!A:AK,26,0) -> JML1 | I40: =VLOOKUP(A40,[2]谷仓DE!A:Q,15,0) -> 16 | J40: =IF(I40=0,"-",IF(VLOOKUP(A40,[2]谷仓DE库龄!A:I,9,0)>365,"≥1 Year",IF(VLOOKUP(A40,[2]谷仓DE库龄!A:I,9,0)>270,"≥9 Months",IF(VLOOKUP(A40,[2]谷仓DE库龄!A:I,9,0)>180,"≥6 Months",IF(VLOOKUP(A40,[2]谷仓DE库龄!A:I,9,0)>90,"≥3 Months","正常"))))) -> ≥1 Year | K40: =IF(VLOOKUP(A40,[2]谷仓DE!A:P,12,0)=0,"",VLOOKUP(A40,[2]谷仓DE!A:P,12,0))
...
